Workbook

Sheet Dashboard
A1: ="Music Academy Ops Snapshot, as of "&TEXT(Data_Audit!F1,"m/d/yyyy") -> Music Academy Ops Snapshot, as of 10/14/2026
A3: Active Students | B3: Monthly Revenue | C3: Inquiry Close Rate | D3: Cancellation Rate | E3: Records Needing Cleanup | F3: Makeups Not Booked
A4: =COUNTIFS(Students[Status__c],"Active") -> 143 | B4: =SUM(Locations[Revenue By Location]) -> 28060 | C4: ='Inquiry Funnel'!J12 -> 0.34453782 | D4: ='Lesson Health'!K17 -> 0.13587604 | E4: =Data_Audit!B2 -> 5 | F4: =Data_Audit!B11 -> 15
G21: What the data says
G22: 1. September looked like a collapse (31 lessons vs. 90 in July), but most
G23: of its lessons were never closed out. Cleaned up, Sept and Aug both hit 64.
G24: 2. Brick cancels 18% of its lessons, almost double Red Bank's 10%.
G25: 23 of Brick's cancellations came from our own instructors, not students.
G26: 3. About 1 in 3 finished inquiries becomes a student (34.5%), not 50%.
G27: 57 leads sat open for over a month, and 19 never got any response.
G29: What I'd fix in Salesforce
G30: 1. A nightly Flow that flags lessons still marked Scheduled after their date,
G31: so they get closed out the next day instead of months later.
G32: 2. Auto-assign new inquiries with a 48-hour follow-up task, and mark leads
G33: Unresponsive automatically after 30 days with no activity.
... G35: and look into why Brick's instructors cancel so often.

Sheet Lessons
A1: CreatedById | B1: CreatedDate | C1: Duration_Minutes__c | D1: Id | E1: Instructor_External_Id__c | F1: Instructor_Name__c | G1: Instructor_Notes__c | H1: Instrument__c | I1: IsDeleted | J1: LastActivityDate | K1: LastModifiedById | L1: LastModifiedDate | M1: LastReferencedDate | N1: LastViewedDate | O1: Lesson_Date__c | P1: Lesson_External_Id__c | Q1: Lesson__c | R1: Location_External_Id__c | S1: Makeup_Required__c | T1: Makeup_Scheduled__c | U1: Name | V1: Start_Time__c | W1: Status__c | X1: Student_External_Id__c | Y1: Student_Name__c | Z1: SystemModstamp | AA1: Does the Instructor teach that Instrument? | AB1: Double Booked Key | AC1: Double Booked? | AD1: Location Name | AE1: Lesson Month | AF1: Is Past
A2: 005ak00000icyWTAAY | B2: 2026-09-14T21:01:58.000Z | C2: 45 | D2: a0Aak00000FtDlZEAV | E2: a06ak00000amzC9AAI | F2: Kai Okafor | G2: Focused on sight reading. | H2: Trumpet | I2: FALSE | K2: 005ak00000icyWTAAY | L2: 2026-09-24T17:45:38.000Z | M2: 2026-09-25T17:55:56.000Z | N2: 2026-09-25T17:55:56.000Z | O2: 46152 | P2: LSN-00001 | Q2: L-0000001 | R2: 131ak000001XjDtAAK | S2: FALSE | T2: FALSE | U2: L-0000001 | V2: 11:00:00.000Z | W2: Completed | X2: a07ak00001rZMp9AAG | Y2: Aurora White | Z2: 2026-09-24T17:45:38.000Z | AA2: =ISNUMBER(SEARCH(";"&Lessons[[#This Row],[Instrument__c]]&";",";"&_xlfn.XLOOKUP(Lessons[[#This Row],[Instructor_External_Id__c]], Instructors[Id], Instructors[Instruments_Taught__c])&";")) -> TRUE | AB2: =IF(LEFT(Lessons[[#This Row],[Status__c]],9)="Cancelled","",Lessons[[#This Row],[Instructor_External_Id__c]]&"|"&TEXT(Lessons[[#This Row],[Lesson_Date__c]],"yyyy-mm-dd")&"|"&Lessons[[#This Row],[Start_Time__c]]) -> a06ak00000amzC9AAI|2026-05-10|11:00:00.000Z | AC2: =IF(Lessons[[#This Row],[Double Booked Key]]="","",COUNTIF(Lessons[Double Booked Key],Lessons[[#This Row],[Double Booked Key]])) -> 1 | AD2: =_xlfn.XLOOKUP(Lessons[[#This Row],[Location_External_Id__c]], Locations[Location Id], Locations[Location Name]) -> Red Bank | AE2: =TEXT(Lessons[[#This Row],[Lesson_Date__c]], "yyyy-mm") -> 2026-05 | AF2: =IF(Lessons[[#This Row],[Lesson_Date__c]]<=Data_Audit!$F$1, "Yes", "No") -> Yes
A3: 005ak00000icyWTAAY | B3: 2026-09-14T21:01:58.000Z | C3: 45 | D3: a0Aak00000FtDlaEAF | E3: a06ak00000amzC9AAI | F3: Kai Okafor | G3: Reviewed last week&#39;s assignment. | H3: Trumpet | I3: FALSE | K3: 005ak00000icyWTAAY | L3: 2026-09-16T17:01:26.000Z | M3: 2026-09-15T18:03:38.000Z | N3: 2026-09-15T18:03:38.000Z | O3: 46062 | P3: LSN-00002 | Q3: L-0000002 | R3: 131ak000001XjDtAAK | S3: FALSE | T3: FALSE | U3: L-0000002 | V3: 16:30:00.000Z | W3: Completed | X3: a07ak00001rZMp9AAG | Y3: Aurora White | Z3: 2026-09-16T17:01:26.000Z | AA3: =ISNUMBER(SEARCH(";"&Lessons[[#This Row],[Instrument__c]]&";",";"&_xlfn.XLOOKUP(Lessons[[#This Row],[Instructor_External_Id__c]], Instructors[Id], Instructors[Instruments_Taught__c])&";")) -> TRUE | AB3: =IF(LEFT(Lessons[[#This Row],[Status__c]],9)="Cancelled","",Lessons[[#This Row],[Instructor_External_Id__c]]&"|"&TEXT(Lessons[[#This Row],[Lesson_Date__c]],"yyyy-mm-dd")&"|"&Lessons[[#This Row],[Start_Time__c]]) -> a06ak00000amzC9AAI|2026-02-09|16:30:00.000Z | AC3: =IF(Lessons[[#This Row],[Double Booked Key]]="","",COUNTIF(Lessons[Double Booked Key],Lessons[[#This Row],[Double Booked Key]])) -> 1 | AD3: =_xlfn.XLOOKUP(Lessons[[#This Row],[Location_External_Id__c]], Locations[Location Id], Locations[Location Name]) -> Red Bank | AE3: =TEXT(Lessons[[#This Row],[Lesson_Date__c]], "yyyy-mm") -> 2026-02 | AF3: =IF(Lessons[[#This Row],[Lesson_Date__c]]<=Data_Audit!$F$1, "Yes", "No") -> Yes
A4: 005ak00000icyWTAAY | B4: 2026-09-14T21:01:58.000Z | C4: 30 | D4: a0Aak00000FtDlbEAF | E4: a06ak00000amzBgAAI | F4: Noah Mitchell | H4: Bass Guitar | I4: FALSE | K4: 005ak00000icyWTAAY | L4: 2026-09-23T19:02:24.000Z | M4: 2026-09-15T17:27:06.000Z | N4: 2026-09-15T17:27:06.000Z | O4: 46289 | P4: LSN-00003 | Q4: L-0000003 | R4: 131ak000001XjDuAAK | S4: FALSE | T4: FALSE | U4: L-0000003 | V4: 17:00:00.000Z | W4: Cancelled by Student | X4: a07ak00001rZMpAAAW | Y4: Mason Wilson | Z4: 2026-09-23T19:02:24.000Z | AA4: =ISNUMBER(SEARCH(";"&Lessons[[#This Row],[Instrument__c]]&";",";"&_xlfn.XLOOKUP(Lessons[[#This Row],[Instructor_External_Id__c]], Instructors[Id], Instructors[Instruments_Taught__c])&";")) -> TRUE | AB4: =IF(LEFT(Lessons[[#This Row],[Status__c]],9)="Cancelled","",Lessons[[#This Row],[Instructor_External_Id__c]]&"|"&TEXT(Lessons[[#This Row],[Lesson_Date__c]],"yyyy-mm-dd")&"|"&Lessons[[#This Row],[Start_Time__c]]) | AC4: =IF(Lessons[[#This Row],[Double Booked Key]]="","",COUNTIF(Lessons[Double Booked Key],Lessons[[#This Row],[Double Booked Key]])) | AD4: =_xlfn.XLOOKUP(Lessons[[#This Row],[Location_External_Id__c]], Locations[Location Id], Locations[Location Name]) -> Brick | AE4: =TEXT(Lessons[[#This Row],[Lesson_Date__c]], "yyyy-mm") -> 2026-09 | AF4: =IF(Lessons[[#This Row],[Lesson_Date__c]]<=Data_Audit!$F$1, "Yes", "No") -> Yes
A5: 005ak00000icyWTAAY | B5: 2026-09-14T21:01:58.000Z | C5: 30 | D5: a0Aak00000FtDlcEAF | E5: a06ak00000amzCFAAY | F5: Valentina Sanchez | G5: Focused on sight reading. | H5: Bass Guitar | I5: FALSE | K5: 005ak00000icyWTAAY | L5: 2026-09-16T16:41:26.000Z | M5: 2026-09-15T17:27:06.000Z | N5: 2026-09-15T17:27:06.000Z | O5: 46092 | P5: LSN-00004 | Q5: L-0000004 | R5: 131ak000001XjDuAAK | S5: FALSE | T5: FALSE | U5: L-0000004 | V5: 19:00:00.000Z | W5: Scheduled | X5: a07ak00001rZMpAAAW | Y5: Mason Wilson | Z5: 2026-09-16T16:41:26.000Z | AA5: =ISNUMBER(SEARCH(";"&Lessons[[#This Row],[Instrument__c]]&";",";"&_xlfn.XLOOKUP(Lessons[[#This Row],[Instructor_External_Id__c]], Instructors[Id], Instructors[Instruments_Taught__c])&";")) -> FALSE | AB5: =IF(LEFT(Lessons[[#This Row],[Status__c]],9)="Cancelled","",Lessons[[#This Row],[Instructor_External_Id__c]]&"|"&TEXT(Lessons[[#This Row],[Lesson_Date__c]],"yyyy-mm-dd")&"|"&Lessons[[#This Row],[Start_Time__c]]) -> a06ak00000amzCFAAY|2026-03-11|19:00:00.000Z | AC5: =IF(Lessons[[#This Row],[Double Booked Key]]="","",COUNTIF(Lessons[Double Booked Key],Lessons[[#This Row],[Double Booked Key]])) -> 1 | AD5: =_xlfn.XLOOKUP(Lessons[[#This Row],[Location_External_Id__c]], Locations[Location Id], Locations[Location Name]) -> Brick | AE5: =TEXT(Lessons[[#This Row],[Lesson_Date__c]], "yyyy-mm") -> 2026-03 | AF5: =IF(Lessons[[#This Row],[Lesson_Date__c]]<=Data_Audit!$F$1, "Yes", "No") -> Yes
A6: 005ak00000icyWTAAY | B6: 2026-09-14T21:01:58.000Z | C6: 45 | D6: a0Aak00000FtDldEAF | E6: a06ak00000amzBvAAI | F6: Caroline Okafor | G6: Worked on scales and timing. | H6: Bass Guitar | I6: FALSE | K6: 005ak00000icyWTAAY | L6: 2026-09-16T17:01:26.000Z | M6: 2026-09-15T17:27:06.000Z | N6: 2026-09-15T17:27:06.000Z | O6: 46146 | P6: LSN-00005 | Q6: L-0000005 | R6: 131ak000001XjDuAAK | S6: FALSE | T6: FALSE | U6: L-0000005 | V6: 16:00:00.000Z | W6: Completed | X6: a07ak00001rZMpAAAW | Y6: Mason Wilson | Z6: 2026-09-16T17:01:26.000Z | AA6: =ISNUMBER(SEARCH(";"&Lessons[[#This Row],[Instrument__c]]&";",";"&_xlfn.XLOOKUP(Lessons[[#This Row],[Instructor_External_Id__c]], Instructors[Id], Instructors[Instruments_Taught__c])&";")) -> TRUE | AB6: =IF(LEFT(Lessons[[#This Row],[Status__c]],9)="Cancelled","",Lessons[[#This Row],[Instructor_External_Id__c]]&"|"&TEXT(Lessons[[#This Row],[Lesson_Date__c]],"yyyy-mm-dd")&"|"&Lessons[[#This Row],[Start_Time__c]]) -> a06ak00000amzBvAAI|2026-05-04|16:00:00.000Z | AC6: =IF(Lessons[[#This Row],[Double Booked Key]]="","",COUNTIF(Lessons[Double Booked Key],Lessons[[#This Row],[Double Booked Key]])) -> 1 | AD6: =_xlfn.XLOOKUP(Lessons[[#This Row],[Location_External_Id__c]], Locations[Location Id], Locations[Location Name]) -> Brick | AE6: =TEXT(Lessons[[#This Row],[Lesson_Date__c]], "yyyy-mm") -> 2026-05 | AF6: =IF(Lessons[[#This Row],[Lesson_Date__c]]<=Data_Audit!$F$1, "Yes", "No") -> Yes
A7: 005ak00000icyWTAAY | B7: 2026-09-14T21:01:58.000Z | C7: 60 | D7: a0Aak00000FtDleEAF | E7: a06ak00000amzBeAAI | F7: Zoey Rodriguez | G7: Good progress on technique. | H7: Cello | I7: FALSE | K7: 005ak00000icyWTAAY | L7: 2026-09-16T17:01:26.000Z | M7: 2026-09-15T17:27:06.000Z | N7: 2026-09-15T17:27:06.000Z | O7: 46267 | P7: LSN-00006 | Q7: L-0000006 | R7: 131ak000001XjDtAAK | S7: FALSE | T7: FALSE | U7: L-0000006 | V7: 10:00:00.000Z | W7: Completed | X7: a07ak00001rZMpBAAW | Y7: Delilah Adams | Z7: 2026-09-16T17:01:26.000Z | AA7: =ISNUMBER(SEARCH(";"&Lessons[[#This Row],[Instrument__c]]&";",";"&_xlfn.XLOOKUP(Lessons[[#This Row],[Instructor_External_Id__c]], Instructors[Id], Instructors[Instruments_Taught__c])&";")) -> TRUE | AB7: =IF(LEFT(Lessons[[#This Row],[Status__c]],9)="Cancelled","",Lessons[[#This Row],[Instructor_External_Id__c]]&"|"&TEXT(Lessons[[#This Row],[Lesson_Date__c]],"yyyy-mm-dd")&"|"&Lessons[[#This Row],[Start_Time__c]]) -> a06ak00000amzBeAAI|2026-09-02|10:00:00.000Z | AC7: =IF(Lessons[[#This Row],[Double Booked Key]]="","",COUNTIF(Lessons[Double Booked Key],Lessons[[#This Row],[Double Booked Key]])) -> 1 | AD7: =_xlfn.XLOOKUP(Lessons[[#This Row],[Location_External_Id__c]], Locations[Location Id], Locations[Location Name]) -> Red Bank | AE7: =TEXT(Lessons[[#This Row],[Lesson_Date__c]], "yyyy-mm") -> 2026-09 | AF7: =IF(Lessons[[#This Row],[Lesson_Date__c]]<=Data_Audit!$F$1, "Yes", "No") -> Yes
A8: 005ak00000icyWTAAY | B8: 2026-09-14T21:01:58.000Z | C8: 60 | D8: a0Aak00000FtDlfEAF | E8: a06ak00000amzBeAAI | F8: Zoey Rodriguez | G8: Reviewed last week&#39;s assignment. | H8: Cello | I8: FALSE | K8: 005ak00000icyWTAAY | L8: 2026-09-16T17:01:26.000Z | M8: 2026-09-15T17:27:06.000Z | N8: 2026-09-15T17:27:06.000Z | O8: 46049 | P8: LSN-00007 | Q8: L-0000007 | R8: 131ak000001XjDtAAK | S8: FALSE | T8: FALSE | U8: L-0000007 | V8: 17:30:00.000Z | W8: Completed | X8: a07ak00001rZMpBAAW | Y8: Delilah Adams | Z8: 2026-09-16T17:01:26.000Z | AA8: =ISNUMBER(SEARCH(";"&Lessons[[#This Row],[Instrument__c]]&";",";"&_xlfn.XLOOKUP(Lessons[[#This Row],[Instructor_External_Id__c]], Instructors[Id], Instructors[Instruments_Taught__c])&";")) -> TRUE | AB8: =IF(LEFT(Lessons[[#This Row],[Status__c]],9)="Cancelled","",Lessons[[#This Row],[Instructor_External_Id__c]]&"|"&TEXT(Lessons[[#This Row],[Lesson_Date__c]],"yyyy-mm-dd")&"|"&Lessons[[#This Row],[Start_Time__c]]) -> a06ak00000amzBeAAI|2026-01-27|17:30:00.000Z | AC8: =IF(Lessons[[#This Row],[Double Booked Key]]="","",COUNTIF(Lessons[Double Booked Key],Lessons[[#This Row],[Double Booked Key]])) -> 1 | AD8: =_xlfn.XLOOKUP(Lessons[[#This Row],[Location_External_Id__c]], Locations[Location Id], Locations[Location Name]) -> Red Bank | AE8: =TEXT(Lessons[[#This Row],[Lesson_Date__c]], "yyyy-mm") -> 2026-01 | AF8: =IF(Lessons[[#This Row],[Lesson_Date__c]]<=Data_Audit!$F$1, "Yes", "No") -> Yes
A9: 005ak00000icyWTAAY | B9: 2026-09-14T21:01:58.000Z | C9: 30 | D9: a0Aak00000FtDlgEAF | E9: a06ak00000amzBeAAI | F9: Zoey Rodriguez | H9: Cello | I9: FALSE | K9: 005ak00000icyWTAAY | L9: 2026-09-16T17:01:26.000Z | M9: 2026-09-15T17:27:06.000Z | N9: 2026-09-15T17:27:06.000Z | O9: 46117 | P9: LSN-00008 | Q9: L-0000008 | R9: 131ak000001XjDtAAK | S9: FALSE | T9: FALSE | U9: L-0000008 | V9: 18:00:00.000Z | W9: No Show | X9: a07ak00001rZMpBAAW | Y9: Delilah Adams | Z9: 2026-09-16T17:01:26.000Z | AA9: =ISNUMBER(SEARCH(";"&Lessons[[#This Row],[Instrument__c]]&";",";"&_xlfn.XLOOKUP(Lessons[[#This Row],[Instructor_External_Id__c]], Instructors[Id], Instructors[Instruments_Taught__c])&";")) -> TRUE | AB9: =IF(LEFT(Lessons[[#This Row],[Status__c]],9)="Cancelled","",Lessons[[#This Row],[Instructor_External_Id__c]]&"|"&TEXT(Lessons[[#This Row],[Lesson_Date__c]],"yyyy-mm-dd")&"|"&Lessons[[#This Row],[Start_Time__c]]) -> a06ak00000amzBeAAI|2026-04-05|18:00:00.000Z | AC9: =IF(Lessons[[#This Row],[Double Booked Key]]="","",COUNTIF(Lessons[Double Booked Key],Lessons[[#This Row],[Double Booked Key]])) -> 1 | AD9: =_xlfn.XLOOKUP(Lessons[[#This Row],[Location_External_Id__c]], Locations[Location Id], Locations[Location Name]) -> Red Bank | AE9: =TEXT(Lessons[[#This Row],[Lesson_Date__c]], "yyyy-mm") -> 2026-04 | AF9: =IF(Lessons[[#This Row],[Lesson_Date__c]]<=Data_Audit!$F$1, "Yes", "No") -> Yes
A10: 005ak00000icyWTAAY | B10: 2026-09-14T21:01:58.000Z | C10: 30 | D10: a0Aak00000FtDlhEAF | E10: a06ak00000amzBeAAI | F10: Zoey Rodriguez | H10: Cello | I10: FALSE | K10: 005ak00000icyWTAAY | L10: 2026-09-16T17:01:26.000Z | M10: 2026-09-15T17:27:06.000Z | N10: 2026-09-15T17:27:06.000Z | O10: 46258 | P10: LSN-00009 | Q10: L-0000009 | R10: 131ak000001XjDtAAK | S10: FALSE | T10: FALSE | U10: L-0000009 | V10: 18:00:00.000Z | W10: No Show | X10: a07ak00001rZMpBAAW | Y10: Delilah Adams | Z10: 2026-09-16T17:01:26.000Z | AA10: =ISNUMBER(SEARCH(";"&Lessons[[#This Row],[Instrument__c]]&";",";"&_xlfn.XLOOKUP(Lessons[[#This Row],[Instructor_External_Id__c]], Instructors[Id], Instructors[Instruments_Taught__c])&";")) -> TRUE | AB10: =IF(LEFT(Lessons[[#This Row],[Status__c]],9)="Cancelled","",Lessons[[#This Row],[Instructor_External_Id__c]]&"|"&TEXT(Lessons[[#This Row],[Lesson_Date__c]],"yyyy-mm-dd")&"|"&Lessons[[#This Row],[Start_Time__c]]) -> a06ak00000amzBeAAI|2026-08-24|18:00:00.000Z | AC10: =IF(Lessons[[#This Row],[Double Booked Key]]="","",COUNTIF(Lessons[Double Booked Key],Lessons[[#This Row],[Double Booked Key]])) -> 1 | AD10: =_xlfn.XLOOKUP(Lessons[[#This Row],[Location_External_Id__c]], Locations[Location Id], Locations[Location Name]) -> Red Bank | AE10: =TEXT(Lessons[[#This Row],[Lesson_Date__c]], "yyyy-mm") -> 2026-08 | AF10: =IF(Lessons[[#This Row],[Lesson_Date__c]]<=Data_Audit!$F$1, "Yes", "No") -> Yes
A11: 005ak00000icyWTAAY | B11: 2026-09-14T21:01:58.000Z | C11: 60 | D11: a0Aak00000FtDliEAF | E11: a06ak00000amzBeAAI | F11: Zoey Rodriguez | H11: Cello | I11: FALSE | K11: 005ak00000icyWTAAY | L11: 2026-09-16T17:01:26.000Z | M11: 2026-09-15T17:27:06.000Z | N11: 2026-09-15T17:27:06.000Z | O11: 46116 | P11: LSN-00010 | Q11: L-0000010 | R11: 131ak000001XjDtAAK | S11: FALSE | T11: FALSE | U11: L-0000010 | V11: 18:30:00.000Z | W11: Cancelled by Student | X11: a07ak00001rZMpBAAW | Y11: Delilah Adams | Z11: 2026-09-16T17:01:26.000Z | AA11: =ISNUMBER(SEARCH(";"&Lessons[[#This Row],[Instrument__c]]&";",";"&_xlfn.XLOOKUP(Lessons[[#This Row],[Instructor_External_Id__c]], Instructors[Id], Instructors[Instruments_Taught__c])&";")) -> TRUE | AB11: =IF(LEFT(Lessons[[#This Row],[Status__c]],9)="Cancelled","",Lessons[[#This Row],[Instructor_External_Id__c]]&"|"&TEXT(Lessons[[#This Row],[Lesson_Date__c]],"yyyy-mm-dd")&"|"&Lessons[[#This Row],[Start_Time__c]]) | AC11: =IF(Lessons[[#This Row],[Double Booked Key]]="","",COUNTIF(Lessons[Double Booked Key],Lessons[[#This Row],[Double Booked Key]])) | AD11: =_xlfn.XLOOKUP(Lessons[[#This Row],[Location_External_Id__c]], Locations[Location Id], Locations[Location Name]) -> Red Bank | AE11: =TEXT(Lessons[[#This Row],[Lesson_Date__c]], "yyyy-mm") -> 2026-04 | AF11: =IF(Lessons[[#This Row],[Lesson_Date__c]]<=Data_Audit!$F$1, "Yes", "No") -> Yes
A12: 005ak00000icyWTAAY | B12: 2026-09-14T21:01:58.000Z | C12: 45 | D12: a0Aak00000FtDljEAF | E12: a06ak00000amzBeAAI | F12: Zoey Rodriguez | G12: Reviewed last week&#39;s assignment. | H12: Cello | I12: FALSE | K12: 005ak00000icyWTAAY | L12: 2026-09-16T17:01:26.000Z | M12: 2026-09-15T17:27:06.000Z | N12: 2026-09-15T17:27:06.000Z | O12: 46109 | P12: LSN-00011 | Q12: L-0000011 | R12: 131ak000001XjDtAAK | S12: FALSE | T12: FALSE | U12: L-0000011 | V12: 18:30:00.000Z | W12: Completed | X12: a07ak00001rZMpBAAW | Y12: Delilah Adams | Z12: 2026-09-16T17:01:26.000Z | AA12: =ISNUMBER(SEARCH(";"&Lessons[[#This Row],[Instrument__c]]&";",";"&_xlfn.XLOOKUP(Lessons[[#This Row],[Instructor_External_Id__c]], Instructors[Id], Instructors[Instruments_Taught__c])&";")) -> TRUE | AB12: =IF(LEFT(Lessons[[#This Row],[Status__c]],9)="Cancelled","",Lessons[[#This Row],[Instructor_External_Id__c]]&"|"&TEXT(Lessons[[#This Row],[Lesson_Date__c]],"yyyy-mm-dd")&"|"&Lessons[[#This Row],[Start_Time__c]]) -> a06ak00000amzBeAAI|2026-03-28|18:30:00.000Z | AC12: =IF(Lessons[[#This Row],[Double Booked Key]]="","",COUNTIF(Lessons[Double Booked Key],Lessons[[#This Row],[Double Booked Key]])) -> 1 | AD12: =_xlfn.XLOOKUP(Lessons[[#This Row],[Location_External_Id__c]], Locations[Location Id], Locations[Location Name]) -> Red Bank | AE12: =TEXT(Lessons[[#This Row],[Lesson_Date__c]], "yyyy-mm") -> 2026-03 | AF12: =IF(Lessons[[#This Row],[Lesson_Date__c]]<=Data_Audit!$F$1, "Yes", "No") -> Yes
A13: 005ak00000icyWTAAY | B13: 2026-09-14T21:01:58.000Z | C13: 45 | D13: a0Aak00000FtDlkEAF | E13: a06ak00000amzBeAAI | F13: Zoey Rodriguez | H13: Cello | I13: FALSE | K13: 005ak00000icyWTAAY | L13: 2026-09-16T17:01:26.000Z | M13: 2026-09-15T17:27:06.000Z | N13: 2026-09-15T17:27:06.000Z | O13: 46287 | P13: LSN-00012 | Q13: L-0000012 | R13: 131ak000001XjDtAAK | S13: TRUE | T13: TRUE | U13: L-0000012 | V13: 15:30:00.000Z | W13: Cancelled by Instructor | X13: a07ak00001rZMpBAAW | Y13: Delilah Adams | Z13: 2026-09-16T17:01:26.000Z | AA13: =ISNUMBER(SEARCH(";"&Lessons[[#This Row],[Instrument__c]]&";",";"&_xlfn.XLOOKUP(Lessons[[#This Row],[Instructor_External_Id__c]], Instructors[Id], Instructors[Instruments_Taught__c])&";")) -> TRUE | AB13: =IF(LEFT(Lessons[[#This Row],[Status__c]],9)="Cancelled","",Lessons[[#This Row],[Instructor_External_Id__c]]&"|"&TEXT(Lessons[[#This Row],[Lesson_Date__c]],"yyyy-mm-dd")&"|"&Lessons[[#This Row],[Start_Time__c]]) | AC13: =IF(Lessons[[#This Row],[Double Booked Key]]="","",COUNTIF(Lessons[Double Booked Key],Lessons[[#This Row],[Double Booked Key]])) | AD13: =_xlfn.XLOOKUP(Lessons[[#This Row],[Location_External_Id__c]], Locations[Location Id], Locations[Location Name]) -> Red Bank | AE13: =TEXT(Lessons[[#This Row],[Lesson_Date__c]], "yyyy-mm") -> 2026-09 | AF13: =IF(Lessons[[#This Row],[Lesson_Date__c]]<=Data_Audit!$F$1, "Yes", "No") -> Yes
A14: 005ak00000icyWTAAY | B14: 2026-09-14T21:01:58.000Z | C14: 60 | D14: a0Aak00000FtDllEAF | E14: a06ak00000amzBeAAI | F14: Zoey Rodriguez | G14: Focused on sight reading. | H14: Cello | I14: FALSE | K14: 005ak00000icyWTAAY | L14: 2026-09-16T17:01:26.000Z | M14: 2026-09-15T17:27:06.000Z | N14: 2026-09-15T17:27:06.000Z | O14: 46197 | P14: LSN-00013 | Q14: L-0000013 | R14: 131ak000001XjDtAAK | S14: FALSE | T14: FALSE | U14: L-0000013 | V14: 15:00:00.000Z | W14: Completed | X14: a07ak00001rZMpBAAW | Y14: Delilah Adams | Z14: 2026-09-16T17:01:26.000Z | AA14: =ISNUMBER(SEARCH(";"&Lessons[[#This Row],[Instrument__c]]&";",";"&_xlfn.XLOOKUP(Lessons[[#This Row],[Instructor_External_Id__c]], Instructors[Id], Instructors[Instruments_Taught__c])&";")) -> TRUE | AB14: =IF(LEFT(Lessons[[#This Row],[Status__c]],9)="Cancelled","",Lessons[[#This Row],[Instructor_External_Id__c]]&"|"&TEXT(Lessons[[#This Row],[Lesson_Date__c]],"yyyy-mm-dd")&"|"&Lessons[[#This Row],[Start_Time__c]]) -> a06ak00000amzBeAAI|2026-06-24|15:00:00.000Z | AC14: =IF(Lessons[[#This Row],[Double Booked Key]]="","",COUNTIF(Lessons[Double Booked Key],Lessons[[#This Row],[Double Booked Key]])) -> 1 | AD14: =_xlfn.XLOOKUP(Lessons[[#This Row],[Location_External_Id__c]], Locations[Location Id], Locations[Location Name]) -> Red Bank | AE14: =TEXT(Lessons[[#This Row],[Lesson_Date__c]], "yyyy-mm") -> 2026-06 | AF14: =IF(Lessons[[#This Row],[Lesson_Date__c]]<=Data_Audit!$F$1, "Yes", "No") -> Yes
A15: 005ak00000icyWTAAY | B15: 2026-09-14T21:01:58.000Z | C15: 30 | D15: a0Aak00000FtDlmEAF | E15: a06ak00000amzBeAAI | F15: Zoey Rodriguez | G15: Worked on scales and timing. | H15: Cello | I15: FALSE | K15: 005ak00000icyWTAAY | L15: 2026-09-16T17:01:26.000Z | M15: 2026-09-15T17:27:06.000Z | N15: 2026-09-15T17:27:06.000Z | O15: 46036 | P15: LSN-00014 | Q15: L-0000014 | R15: 131ak000001XjDtAAK | S15: FALSE | T15: FALSE | U15: L-0000014 | V15: 16:30:00.000Z | W15: Completed | X15: a07ak00001rZMpBAAW | Y15: Delilah Adams | Z15: 2026-09-16T17:01:26.000Z | AA15: =ISNUMBER(SEARCH(";"&Lessons[[#This Row],[Instrument__c]]&";",";"&_xlfn.XLOOKUP(Lessons[[#This Row],[Instructor_External_Id__c]], Instructors[Id], Instructors[Instruments_Taught__c])&";")) -> TRUE | AB15: =IF(LEFT(Lessons[[#This Row],[Status__c]],9)="Cancelled","",Lessons[[#This Row],[Instructor_External_Id__c]]&"|"&TEXT(Lessons[[#This Row],[Lesson_Date__c]],"yyyy-mm-dd")&"|"&Lessons[[#This Row],[Start_Time__c]]) -> a06ak00000amzBeAAI|2026-01-14|16:30:00.000Z | AC15: =IF(Lessons[[#This Row],[Double Booked Key]]="","",COUNTIF(Lessons[Double Booked Key],Lessons[[#This Row],[Double Booked Key]])) -> 1 | AD15: =_xlfn.XLOOKUP(Lessons[[#This Row],[Location_External_Id__c]], Locations[Location Id], Locations[Location Name]) -> Red Bank | AE15: =TEXT(Lessons[[#This Row],[Lesson_Date__c]], "yyyy-mm") -> 2026-01 | AF15: =IF(Lessons[[#This Row],[Lesson_Date__c]]<=Data_Audit!$F$1, "Yes", "No") -> Yes
A16: 005ak00000icyWTAAY | B16: 2026-09-14T21:01:58.000Z | C16: 60 | D16: a0Aak00000FtDlnEAF | E16: a06ak00000amzBhAAI | F16: Layla Sullivan | H16: Ukulele | I16: FALSE | K16: 005ak00000icyWTAAY | L16: 2026-09-16T17:01:26.000Z | M16: 2026-09-15T17:27:06.000Z | N16: 2026-09-15T17:27:06.000Z | O16: 46063 | P16: LSN-00015 | Q16: L-0000015 | R16: 131ak000001XjDvAAK | S16: FALSE | T16: FALSE | U16: L-0000015 | V16: 17:30:00.000Z | W16: Cancelled by Student | X16: a07ak00001rZMpCAAW | Y16: Logan Jackson | Z16: 2026-09-16T17:01:26.000Z | AA16: =ISNUMBER(SEARCH(";"&Lessons[[#This Row],[Instrument__c]]&";",";"&_xlfn.XLOOKUP(Lessons[[#This Row],[Instructor_External_Id__c]], Instructors[Id], Instructors[Instruments_Taught__c])&";")) -> TRUE | AB16: =IF(LEFT(Lessons[[#This Row],[Status__c]],9)="Cancelled","",Lessons[[#This Row],[Instructor_External_Id__c]]&"|"&TEXT(Lessons[[#This Row],[Lesson_Date__c]],"yyyy-mm-dd")&"|"&Lessons[[#This Row],[Start_Time__c]]) | AC16: =IF(Lessons[[#This Row],[Double Booked Key]]="","",COUNTIF(Lessons[Double Booked Key],Lessons[[#This Row],[Double Booked Key]])) | AD16: =_xlfn.XLOOKUP(Lessons[[#This Row],[Location_External_Id__c]], Locations[Location Id], Locations[Location Name]) -> Toms River | AE16: =TEXT(Lessons[[#This Row],[Lesson_Date__c]], "yyyy-mm") -> 2026-02 | AF16: =IF(Lessons[[#This Row],[Lesson_Date__c]]<=Data_Audit!$F$1, "Yes", "No") -> Yes
A17: 005ak00000icyWTAAY | B17: 2026-09-14T21:01:58.000Z | C17: 30 | D17: a0Aak00000FtDloEAF | E17: a06ak00000amzBhAAI | F17: Layla Sullivan | H17: Ukulele | I17: FALSE | K17: 005ak00000icyWTAAY | L17: 2026-09-16T17:01:26.000Z | M17: 2026-09-15T17:27:06.000Z | N17: 2026-09-15T17:27:06.000Z | O17: 46089 | P17: LSN-00016 | Q17: L-0000016 | R17: 131ak000001XjDvAAK | S17: FALSE | T17: FALSE | U17: L-0000016 | V17: 15:00:00.000Z | W17: Cancelled by Student | X17: a07ak00001rZMpCAAW | Y17: Logan Jackson | Z17: 2026-09-16T17:01:26.000Z | AA17: =ISNUMBER(SEARCH(";"&Lessons[[#This Row],[Instrument__c]]&";",";"&_xlfn.XLOOKUP(Lessons[[#This Row],[Instructor_External_Id__c]], Instructors[Id], Instructors[Instruments_Taught__c])&";")) -> TRUE | AB17: =IF(LEFT(Lessons[[#This Row],[Status__c]],9)="Cancelled","",Lessons[[#This Row],[Instructor_External_Id__c]]&"|"&TEXT(Lessons[[#This Row],[Lesson_Date__c]],"yyyy-mm-dd")&"|"&Lessons[[#This Row],[Start_Time__c]]) | AC17: =IF(Lessons[[#This Row],[Double Booked Key]]="","",COUNTIF(Lessons[Double Booked Key],Lessons[[#This Row],[Double Booked Key]])) | AD17: =_xlfn.XLOOKUP(Lessons[[#This Row],[Location_External_Id__c]], Locations[Location Id], Locations[Location Name]) -> Toms River | AE17: =TEXT(Lessons[[#This Row],[Lesson_Date__c]], "yyyy-mm") -> 2026-03 | AF17: =IF(Lessons[[#This Row],[Lesson_Date__c]]<=Data_Audit!$F$1, "Yes", "No") -> Yes
A18: 005ak00000icyWTAAY | B18: 2026-09-14T21:01:58.000Z | C18: 60 | D18: a0Aak00000FtDlpEAF | E18: a06ak00000amzBhAAI | F18: Layla Sullivan | G18: Focused on sight reading. | H18: Ukulele | I18: FALSE | K18: 005ak00000icyWTAAY | L18: 2026-09-16T17:01:26.000Z | M18: 2026-09-15T17:27:06.000Z | N18: 2026-09-15T17:27:06.000Z | O18: 46160 | P18: LSN-00017 | Q18: L-0000017 | R18: 131ak000001XjDvAAK | S18: FALSE | T18: FALSE | U18: L-0000017 | V18: 17:00:00.000Z | W18: Completed | X18: a07ak00001rZMpCAAW | Y18: Logan Jackson | Z18: 2026-09-16T17:01:26.000Z | AA18: =ISNUMBER(SEARCH(";"&Lessons[[#This Row],[Instrument__c]]&";",";"&_xlfn.XLOOKUP(Lessons[[#This Row],[Instructor_External_Id__c]], Instructors[Id], Instructors[Instruments_Taught__c])&";")) -> TRUE | AB18: =IF(LEFT(Lessons[[#This Row],[Status__c]],9)="Cancelled","",Lessons[[#This Row],[Instructor_External_Id__c]]&"|"&TEXT(Lessons[[#This Row],[Lesson_Date__c]],"yyyy-mm-dd")&"|"&Lessons[[#This Row],[Start_Time__c]]) -> a06ak00000amzBhAAI|2026-05-18|17:00:00.000Z | AC18: =IF(Lessons[[#This Row],[Double Booked Key]]="","",COUNTIF(Lessons[Double Booked Key],Lessons[[#This Row],[Double Booked Key]])) -> 1 | AD18: =_xlfn.XLOOKUP(Lessons[[#This Row],[Location_External_Id__c]], Locations[Location Id], Locations[Location Name]) -> Toms River | AE18: =TEXT(Lessons[[#This Row],[Lesson_Date__c]], "yyyy-mm") -> 2026-05 | AF18: =IF(Lessons[[#This Row],[Lesson_Date__c]]<=Data_Audit!$F$1, "Yes", "No") -> Yes
A19: 005ak00000icyWTAAY | B19: 2026-09-14T21:01:58.000Z | C19: 45 | D19: a0Aak00000FtDlqEAF | E19: a06ak00000amzBhAAI | F19: Layla Sullivan | H19: Ukulele | I19: FALSE | K19: 005ak00000icyWTAAY | L19: 2026-09-16T17:01:26.000Z | M19: 2026-09-16T16:49:23.000Z | N19: 2026-09-16T16:49:23.000Z | O19: 46239 | P19: LSN-00018 | Q19: L-0000018 | R19: 131ak000001XjDvAAK | S19: FALSE | T19: FALSE | U19: L-0000018 | V19: 19:00:00.000Z | W19: Completed | X19: a07ak00001rZMpCAAW | Y19: Logan Jackson | Z19: 2026-09-16T17:01:26.000Z | AA19: =ISNUMBER(SEARCH(";"&Lessons[[#This Row],[Instrument__c]]&";",";"&_xlfn.XLOOKUP(Lessons[[#This Row],[Instructor_External_Id__c]], Instructors[Id], Instructors[Instruments_Taught__c])&";")) -> TRUE | AB19: =IF(LEFT(Lessons[[#This Row],[Status__c]],9)="Cancelled","",Lessons[[#This Row],[Instructor_External_Id__c]]&"|"&TEXT(Lessons[[#This Row],[Lesson_Date__c]],"yyyy-mm-dd")&"|"&Lessons[[#This Row],[Start_Time__c]]) -> a06ak00000amzBhAAI|2026-08-05|19:00:00.000Z | AC19: =IF(Lessons[[#This Row],[Double Booked Key]]="","",COUNTIF(Lessons[Double Booked Key],Lessons[[#This Row],[Double Booked Key]])) -> 1 | AD19: =_xlfn.XLOOKUP(Lessons[[#This Row],[Location_External_Id__c]], Locations[Location Id], Locations[Location Name]) -> Toms River | AE19: =TEXT(Lessons[[#This Row],[Lesson_Date__c]], "yyyy-mm") -> 2026-08 | AF19: =IF(Lessons[[#This Row],[Lesson_Date__c]]<=Data_Audit!$F$1, "Yes", "No") -> Yes
A20: 005ak00000icyWTAAY | B20: 2026-09-14T21:01:58.000Z | C20: 60 | D20: a0Aak00000FtDlrEAF | E20: a06ak00000amzBhAAI | F20: Layla Sullivan | G20: Started new piece. | H20: Ukulele | I20: FALSE | K20: 005ak00000icyWTAAY | L20: 2026-09-16T17:01:26.000Z | M20: 2026-09-15T17:27:06.000Z | N20: 2026-09-15T17:27:06.000Z | O20: 46214 | P20: LSN-00019 | Q20: L-0000019 | R20: 131ak000001XjDvAAK | S20: FALSE | T20: FALSE | U20: L-0000019 | V20: 17:30:00.000Z | W20: Completed | X20: a07ak00001rZMpCAAW | Y20: Logan Jackson | Z20: 2026-09-16T17:01:26.000Z | AA20: =ISNUMBER(SEARCH(";"&Lessons[[#This Row],[Instrument__c]]&";",";"&_xlfn.XLOOKUP(Lessons[[#This Row],[Instructor_External_Id__c]], Instructors[Id], Instructors[Instruments_Taught__c])&";")) -> TRUE | AB20: =IF(LEFT(Lessons[[#This Row],[Status__c]],9)="Cancelled","",Lessons[[#This Row],[Instructor_External_Id__c]]&"|"&TEXT(Lessons[[#This Row],[Lesson_Date__c]],"yyyy-mm-dd")&"|"&Lessons[[#This Row],[Start_Time__c]]) -> a06ak00000amzBhAAI|2026-07-11|17:30:00.000Z | AC20: =IF(Lessons[[#This Row],[Double Booked Key]]="","",COUNTIF(Lessons[Double Booked Key],Lessons[[#This Row],[Double Booked Key]])) -> 1 | AD20: =_xlfn.XLOOKUP(Lessons[[#This Row],[Location_External_Id__c]], Locations[Location Id], Locations[Location Name]) -> Toms River | AE20: =TEXT(Lessons[[#This Row],[Lesson_Date__c]], "yyyy-mm") -> 2026-07 | AF20: =IF(Lessons[[#This Row],[Lesson_Date__c]]<=Data_Audit!$F$1, "Yes", "No") -> Yes
A21: 005ak00000icyWTAAY | B21: 2026-09-14T21:01:58.000Z | C21: 45 | D21: a0Aak00000FtDlsEAF | E21: a06ak00000amzBhAAI | F21: Layla Sullivan | G21: Good progress on technique. | H21: Ukulele | I21: FALSE | K21: 005ak00000icyWTAAY | L21: 2026-09-16T17:01:26.000Z | M21: 2026-09-15T17:27:06.000Z | N21: 2026-09-15T17:27:06.000Z | O21: 46193 | P21: LSN-00020 | Q21: L-0000020 | R21: 131ak000001XjDvAAK | S21: FALSE | T21: FALSE | U21: L-0000020 | V21: 16:30:00.000Z | W21: Completed | X21: a07ak00001rZMpCAAW | Y21: Logan Jackson | Z21: 2026-09-16T17:01:26.000Z | AA21: =ISNUMBER(SEARCH(";"&Lessons[[#This Row],[Instrument__c]]&";",";"&_xlfn.XLOOKUP(Lessons[[#This Row],[Instructor_External_Id__c]], Instructors[Id], Instructors[Instruments_Taught__c])&";")) -> TRUE | AB21: =IF(LEFT(Lessons[[#This Row],[Status__c]],9)="Cancelled","",Lessons[[#This Row],[Instructor_External_Id__c]]&"|"&TEXT(Lessons[[#This Row],[Lesson_Date__c]],"yyyy-mm-dd")&"|"&Lessons[[#This Row],[Start_Time__c]]) -> a06ak00000amzBhAAI|2026-06-20|16:30:00.000Z | AC21: =IF(Lessons[[#This Row],[Double Booked Key]]="","",COUNTIF(Lessons[Double Booked Key],Lessons[[#This Row],[Double Booked Key]])) -> 1 | AD21: =_xlfn.XLOOKUP(Lessons[[#This Row],[Location_External_Id__c]], Locations[Location Id], Locations[Location Name]) -> Toms River | AE21: =TEXT(Lessons[[#This Row],[Lesson_Date__c]], "yyyy-mm") -> 2026-06 | AF21: =IF(Lessons[[#This Row],[Lesson_Date__c]]<=Data_Audit!$F$1, "Yes", "No") -> Yes
A22: 005ak00000icyWTAAY | B22: 2026-09-14T21:01:58.000Z | C22: 60 | D22: a0Aak00000FtDltEAF | E22: a06ak00000amzBhAAI | F22: Layla Sullivan | H22: Ukulele | I22: FALSE | K22: 005ak00000icyWTAAY | L22: 2026-09-25T18:00:49.000Z | M22: 2026-09-15T17:27:06.000Z | N22: 2026-09-15T17:27:06.000Z | O22: 46242 | P22: LSN-00021 | Q22: L-0000021 | R22: 131ak000001XjDvAAK | S22: TRUE | T22: TRUE | U22: L-0000021 | V22: 16:00:00.000Z | W22: Cancelled by Instructor | X22: a07ak00001rZMpCAAW | Y22: Logan Jackson | Z22: 2026-09-25T18:00:49.000Z | AA22: =ISNUMBER(SEARCH(";"&Lessons[[#This Row],[Instrument__c]]&";",";"&_xlfn.XLOOKUP(Lessons[[#This Row],[Instructor_External_Id__c]], Instructors[Id], Instructors[Instruments_Taught__c])&";")) -> TRUE | AB22: =IF(LEFT(Lessons[[#This Row],[Status__c]],9)="Cancelled","",Lessons[[#This Row],[Instructor_External_Id__c]]&"|"&TEXT(Lessons[[#This Row],[Lesson_Date__c]],"yyyy-mm-dd")&"|"&Lessons[[#This Row],[Start_Time__c]]) | AC22: =IF(Lessons[[#This Row],[Double Booked Key]]="","",COUNTIF(Lessons[Double Booked Key],Lessons[[#This Row],[Double Booked Key]])) | AD22: =_xlfn.XLOOKUP(Lessons[[#This Row],[Location_External_Id__c]], Locations[Location Id], Locations[Location Name]) -> Toms River | AE22: =TEXT(Lessons[[#This Row],[Lesson_Date__c]], "yyyy-mm") -> 2026-08 | AF22: =IF(Lessons[[#This Row],[Lesson_Date__c]]<=Data_Audit!$F$1, "Yes", "No") -> Yes
A23: 005ak00000icyWTAAY | B23: 2026-09-14T21:01:58.000Z | C23: 45 | D23: a0Aak00000FtDluEAF | E23: a06ak00000amzBhAAI | F23: Layla Sullivan | G23: Worked on scales and timing. | H23: Ukulele | I23: FALSE | K23: 005ak00000icyWTAAY | L23: 2026-09-16T17:01:26.000Z | M23: 2026-09-15T17:27:06.000Z | N23: 2026-09-15T17:27:06.000Z | O23: 46255 | P23: LSN-00022 | Q23: L-0000022 | R23: 131ak000001XjDvAAK | S23: FALSE | T23: FALSE | U23: L-0000022 | V23: 11:00:00.000Z | W23: Completed | X23: a07ak00001rZMpCAAW | Y23: Logan Jackson | Z23: 2026-09-16T17:01:26.000Z | AA23: =ISNUMBER(SEARCH(";"&Lessons[[#This Row],[Instrument__c]]&";",";"&_xlfn.XLOOKUP(Lessons[[#This Row],[Instructor_External_Id__c]], Instructors[Id], Instructors[Instruments_Taught__c])&";")) -> TRUE | AB23: =IF(LEFT(Lessons[[#This Row],[Status__c]],9)="Cancelled","",Lessons[[#This Row],[Instructor_External_Id__c]]&"|"&TEXT(Lessons[[#This Row],[Lesson_Date__c]],"yyyy-mm-dd")&"|"&Lessons[[#This Row],[Start_Time__c]]) -> a06ak00000amzBhAAI|2026-08-21|11:00:00.000Z | AC23: =IF(Lessons[[#This Row],[Double Booked Key]]="","",COUNTIF(Lessons[Double Booked Key],Lessons[[#This Row],[Double Booked Key]])) -> 1 | AD23: =_xlfn.XLOOKUP(Lessons[[#This Row],[Location_External_Id__c]], Locations[Location Id], Locations[Location Name]) -> Toms River | AE23: =TEXT(Lessons[[#This Row],[Lesson_Date__c]], "yyyy-mm") -> 2026-08 | AF23: =IF(Lessons[[#This Row],[Lesson_Date__c]]<=Data_Audit!$F$1, "Yes", "No") -> Yes
A24: 005ak00000icyWTAAY | B24: 2026-09-14T21:01:58.000Z | C24: 45 | D24: a0Aak00000FtDlvEAF | E24: a06ak00000amzBhAAI | F24: Layla Sullivan | G24: Worked on scales and timing. | H24: Ukulele | I24: FALSE | K24: 005ak00000icyWTAAY | L24: 2026-09-16T17:01:26.000Z | M24: 2026-09-15T17:27:06.000Z | N24: 2026-09-15T17:27:06.000Z | O24: 46031 | P24: LSN-00023 | Q24: L-0000023 | R24: 131ak000001XjDvAAK | S24: FALSE | T24: FALSE | U24: L-0000023 | V24: 10:00:00.000Z | W24: Completed | X24: a07ak00001rZMpCAAW | Y24: Logan Jackson | Z24: 2026-09-16T17:01:26.000Z | AA24: =ISNUMBER(SEARCH(";"&Lessons[[#This Row],[Instrument__c]]&";",";"&_xlfn.XLOOKUP(Lessons[[#This Row],[Instructor_External_Id__c]], Instructors[Id], Instructors[Instruments_Taught__c])&";")) -> TRUE | AB24: =IF(LEFT(Lessons[[#This Row],[Status__c]],9)="Cancelled","",Lessons[[#This Row],[Instructor_External_Id__c]]&"|"&TEXT(Lessons[[#This Row],[Lesson_Date__c]],"yyyy-mm-dd")&"|"&Lessons[[#This Row],[Start_Time__c]]) -> a06ak00000amzBhAAI|2026-01-09|10:00:00.000Z | AC24: =IF(Lessons[[#This Row],[Double Booked Key]]="","",COUNTIF(Lessons[Double Booked Key],Lessons[[#This Row],[Double Booked Key]])) -> 1 | AD24: =_xlfn.XLOOKUP(Lessons[[#This Row],[Location_External_Id__c]], Locations[Location Id], Locations[Location Name]) -> Toms River | AE24: =TEXT(Lessons[[#This Row],[Lesson_Date__c]], "yyyy-mm") -> 2026-01 | AF24: =IF(Lessons[[#This Row],[Lesson_Date__c]]<=Data_Audit!$F$1, "Yes", "No") -> Yes
A25: 005ak00000icyWTAAY | B25: 2026-09-14T21:01:58.000Z | C25: 60 | D25: a0Aak00000FtDlwEAF | E25: a06ak00000amzBgAAI | F25: Noah Mitchell | H25: Bass Guitar | I25: FALSE | K25: 005ak00000icyWTAAY | L25: 2026-09-25T18:00:49.000Z | M25: 2026-09-15T17:27:06.000Z | N25: 2026-09-15T17:27:06.000Z | O25: 46130 | P25: LSN-00024 | Q25: L-0000024 | R25: 131ak000001XjDuAAK | S25: TRUE | T25: TRUE | U25: L-0000024 | V25: 10:00:00.000Z | W25: Cancelled by Instructor | X25: a07ak00001rZMpDAAW | Y25: Mei Thompson | Z25: 2026-09-25T18:00:49.000Z | AA25: =ISNUMBER(SEARCH(";"&Lessons[[#This Row],[Instrument__c]]&";",";"&_xlfn.XLOOKUP(Lessons[[#This Row],[Instructor_External_Id__c]], Instructors[Id], Instructors[Instruments_Taught__c])&";")) -> TRUE | AB25: =IF(LEFT(Lessons[[#This Row],[Status__c]],9)="Cancelled","",Lessons[[#This Row],[Instructor_External_Id__c]]&"|"&TEXT(Lessons[[#This Row],[Lesson_Date__c]],"yyyy-mm-dd")&"|"&Lessons[[#This Row],[Start_Time__c]]) | AC25: =IF(Lessons[[#This Row],[Double Booked Key]]="","",COUNTIF(Lessons[Double Booked Key],Lessons[[#This Row],[Double Booked Key]])) | AD25: =_xlfn.XLOOKUP(Lessons[[#This Row],[Location_External_Id__c]], Locations[Location Id], Locations[Location Name]) -> Brick | AE25: =TEXT(Lessons[[#This Row],[Lesson_Date__c]], "yyyy-mm") -> 2026-04 | AF25: =IF(Lessons[[#This Row],[Lesson_Date__c]]<=Data_Audit!$F$1, "Yes", "No") -> Yes
A26: 005ak00000icyWTAAY | B26: 2026-09-14T21:01:58.000Z | C26: 45 | D26: a0Aak00000FtDlxEAF | E26: a06ak00000amzBgAAI | F26: Noah Mitchell | G26: Started new piece. | H26: Bass Guitar | I26: FALSE | K26: 005ak00000icyWTAAY | L26: 2026-09-16T17:01:26.000Z | M26: 2026-09-15T17:27:06.000Z | N26: 2026-09-15T17:27:06.000Z | O26: 46290 | P26: LSN-00025 | Q26: L-0000025 | R26: 131ak000001XjDuAAK | S26: FALSE | T26: FALSE | U26: L-0000025 | V26: 16:00:00.000Z | W26: Completed | X26: a07ak00001rZMpDAAW | Y26: Mei Thompson | Z26: 2026-09-16T17:01:26.000Z | AA26: =ISNUMBER(SEARCH(";"&Lessons[[#This Row],[Instrument__c]]&";",";"&_xlfn.XLOOKUP(Lessons[[#This Row],[Instructor_External_Id__c]], Instructors[Id], Instructors[Instruments_Taught__c])&";")) -> TRUE | AB26: =IF(LEFT(Lessons[[#This Row],[Status__c]],9)="Cancelled","",Lessons[[#This Row],[Instructor_External_Id__c]]&"|"&TEXT(Lessons[[#This Row],[Lesson_Date__c]],"yyyy-mm-dd")&"|"&Lessons[[#This Row],[Start_Time__c]]) -> a06ak00000amzBgAAI|2026-09-25|16:00:00.000Z | AC26: =IF(Lessons[[#This Row],[Double Booked Key]]="","",COUNTIF(Lessons[Double Booked Key],Lessons[[#This Row],[Double Booked Key]])) -> 1 | AD26: =_xlfn.XLOOKUP(Lessons[[#This Row],[Location_External_Id__c]], Locations[Location Id], Locations[Location Name]) -> Brick | AE26: =TEXT(Lessons[[#This Row],[Lesson_Date__c]], "yyyy-mm") -> 2026-09 | AF26: =IF(Lessons[[#This Row],[Lesson_Date__c]]<=Data_Audit!$F$1, "Yes", "No") -> Yes
A27: 005ak00000icyWTAAY | B27: 2026-09-14T21:01:58.000Z | C27: 30 | D27: a0Aak00000FtDlyEAF | E27: a06ak00000amzBgAAI | F27: Noah Mitchell | G27: Worked on scales and timing. | H27: Bass Guitar | I27: FALSE | K27: 005ak00000icyWTAAY | L27: 2026-09-16T17:01:26.000Z | M27: 2026-09-15T17:27:06.000Z | N27: 2026-09-15T17:27:06.000Z | O27: 46212 | P27: LSN-00026 | Q27: L-0000026 | R27: 131ak000001XjDuAAK | S27: FALSE | T27: FALSE | U27: L-0000026 | V27: 16:00:00.000Z | W27: Completed | X27: a07ak00001rZMpDAAW | Y27: Mei Thompson | Z27: 2026-09-16T17:01:26.000Z | AA27: =ISNUMBER(SEARCH(";"&Lessons[[#This Row],[Instrument__c]]&";",";"&_xlfn.XLOOKUP(Lessons[[#This Row],[Instructor_External_Id__c]], Instructors[Id], Instructors[Instruments_Taught__c])&";")) -> TRUE | AB27: =IF(LEFT(Lessons[[#This Row],[Status__c]],9)="Cancelled","",Lessons[[#This Row],[Instructor_External_Id__c]]&"|"&TEXT(Lessons[[#This Row],[Lesson_Date__c]],"yyyy-mm-dd")&"|"&Lessons[[#This Row],[Start_Time__c]]) -> a06ak00000amzBgAAI|2026-07-09|16:00:00.000Z | AC27: =IF(Lessons[[#This Row],[Double Booked Key]]="","",COUNTIF(Lessons[Double Booked Key],Lessons[[#This Row],[Double Booked Key]])) -> 1 | AD27: =_xlfn.XLOOKUP(Lessons[[#This Row],[Location_External_Id__c]], Locations[Location Id], Locations[Location Name]) -> Brick | AE27: =TEXT(Lessons[[#This Row],[Lesson_Date__c]], "yyyy-mm") -> 2026-07 | AF27: =IF(Lessons[[#This Row],[Lesson_Date__c]]<=Data_Audit!$F$1, "Yes", "No") -> Yes
A28: 005ak00000icyWTAAY | B28: 2026-09-14T21:01:58.000Z | C28: 45 | D28: a0Aak00000FtDlzEAF | E28: a06ak00000amzBgAAI | F28: Noah Mitchell | G28: Worked on scales and timing. | H28: Bass Guitar | I28: FALSE | K28: 005ak00000icyWTAAY | L28: 2026-09-16T17:01:26.000Z | M28: 2026-09-15T17:27:06.000Z | N28: 2026-09-15T17:27:06.000Z | O28: 46240 | P28: LSN-00027 | Q28: L-0000027 | R28: 131ak000001XjDuAAK | S28: FALSE | T28: FALSE | U28: L-0000027 | V28: 15:00:00.000Z | W28: Completed | X28: a07ak00001rZMpDAAW | Y28: Mei Thompson | Z28: 2026-09-16T17:01:26.000Z | AA28: =ISNUMBER(SEARCH(";"&Lessons[[#This Row],[Instrument__c]]&";",";"&_xlfn.XLOOKUP(Lessons[[#This Row],[Instructor_External_Id__c]], Instructors[Id], Instructors[Instruments_Taught__c])&";")) -> TRUE | AB28: =IF(LEFT(Lessons[[#This Row],[Status__c]],9)="Cancelled","",Lessons[[#This Row],[Instructor_External_Id__c]]&"|"&TEXT(Lessons[[#This Row],[Lesson_Date__c]],"yyyy-mm-dd")&"|"&Lessons[[#This Row],[Start_Time__c]]) -> a06ak00000amzBgAAI|2026-08-06|15:00:00.000Z | AC28: =IF(Lessons[[#This Row],[Double Booked Key]]="","",COUNTIF(Lessons[Double Booked Key],Lessons[[#This Row],[Double Booked Key]])) -> 1 | AD28: =_xlfn.XLOOKUP(Lessons[[#This Row],[Location_External_Id__c]], Locations[Location Id], Locations[Location Name]) -> Brick | AE28: =TEXT(Lessons[[#This Row],[Lesson_Date__c]], "yyyy-mm") -> 2026-08 | AF28: =IF(Lessons[[#This Row],[Lesson_Date__c]]<=Data_Audit!$F$1, "Yes", "No") -> Yes
A29: 005ak00000icyWTAAY | B29: 2026-09-14T21:01:58.000Z | C29: 45 | D29: a0Aak00000FtDm0EAF | E29: a06ak00000amzBgAAI | F29: Noah Mitchell | G29: Reviewed last week&#39;s assignment. | H29: Bass Guitar | I29: FALSE | K29: 005ak00000icyWTAAY | L29: 2026-09-16T17:01:26.000Z | M29: 2026-09-15T17:27:06.000Z | N29: 2026-09-15T17:27:06.000Z | O29: 46292 | P29: LSN-00028 | Q29: L-0000028 | R29: 131ak000001XjDuAAK | S29: FALSE | T29: FALSE | U29: L-0000028 | V29: 10:00:00.000Z | W29: Completed | X29: a07ak00001rZMpDAAW | Y29: Mei Thompson | Z29: 2026-09-16T17:01:26.000Z | AA29: =ISNUMBER(SEARCH(";"&Lessons[[#This Row],[Instrument__c]]&";",";"&_xlfn.XLOOKUP(Lessons[[#This Row],[Instructor_External_Id__c]], Instructors[Id], Instructors[Instruments_Taught__c])&";")) -> TRUE | AB29: =IF(LEFT(Lessons[[#This Row],[Status__c]],9)="Cancelled","",Lessons[[#This Row],[Instructor_External_Id__c]]&"|"&TEXT(Lessons[[#This Row],[Lesson_Date__c]],"yyyy-mm-dd")&"|"&Lessons[[#This Row],[Start_Time__c]]) -> a06ak00000amzBgAAI|2026-09-27|10:00:00.000Z | AC29: =IF(Lessons[[#This Row],[Double Booked Key]]="","",COUNTIF(Lessons[Double Booked Key],Lessons[[#This Row],[Double Booked Key]])) -> 1 | AD29: =_xlfn.XLOOKUP(Lessons[[#This Row],[Location_External_Id__c]], Locations[Location Id], Locations[Location Name]) -> Brick | AE29: =TEXT(Lessons[[#This Row],[Lesson_Date__c]], "yyyy-mm") -> 2026-09 | AF29: =IF(Lessons[[#This Row],[Lesson_Date__c]]<=Data_Audit!$F$1, "Yes", "No") -> Yes
A30: 005ak00000icyWTAAY | B30: 2026-09-14T21:01:58.000Z | C30: 45 | D30: a0Aak00000FtDm1EAF | E30: a06ak00000amzBgAAI | F30: Noah Mitchell | G30: Started new piece. | H30: Bass Guitar | I30: FALSE | K30: 005ak00000icyWTAAY | L30: 2026-09-16T17:01:26.000Z | M30: 2026-09-15T17:27:06.000Z | N30: 2026-09-15T17:27:06.000Z | O30: 46041 | P30: LSN-00029 | Q30: L-0000029 | R30: 131ak000001XjDuAAK | S30: FALSE | T30: FALSE | U30: L-0000029 | V30: 17:00:00.000Z | W30: Completed | X30: a07ak00001rZMpDAAW | Y30: Mei Thompson | Z30: 2026-09-16T17:01:26.000Z | AA30: =ISNUMBER(SEARCH(";"&Lessons[[#This Row],[Instrument__c]]&";",";"&_xlfn.XLOOKUP(Lessons[[#This Row],[Instructor_External_Id__c]], Instructors[Id], Instructors[Instruments_Taught__c])&";")) -> TRUE | AB30: =IF(LEFT(Lessons[[#This Row],[Status__c]],9)="Cancelled","",Lessons[[#This Row],[Instructor_External_Id__c]]&"|"&TEXT(Lessons[[#This Row],[Lesson_Date__c]],"yyyy-mm-dd")&"|"&Lessons[[#This Row],[Start_Time__c]]) -> a06ak00000amzBgAAI|2026-01-19|17:00:00.000Z | AC30: =IF(Lessons[[#This Row],[Double Booked Key]]="","",COUNTIF(Lessons[Double Booked Key],Lessons[[#This Row],[Double Booked Key]])) -> 1 | AD30: =_xlfn.XLOOKUP(Lessons[[#This Row],[Location_External_Id__c]], Locations[Location Id], Locations[Location Name]) -> Brick | AE30: =TEXT(Lessons[[#This Row],[Lesson_Date__c]], "yyyy-mm") -> 2026-01 | AF30: =IF(Lessons[[#This Row],[Lesson_Date__c]]<=Data_Audit!$F$1, "Yes", "No") -> Yes
A31: 005ak00000icyWTAAY | B31: 2026-09-14T21:01:58.000Z | C31: 30 | D31: a0Aak00000FtDm2EAF | E31: a06ak00000amzCJAAY | F31: Sofia Harris | H31: Violin | I31: FALSE | K31: 005ak00000icyWTAAY | L31: 2026-09-16T17:01:26.000Z | M31: 2026-09-15T17:27:06.000Z | N31: 2026-09-15T17:27:06.000Z | O31: 46157 | P31: LSN-00030 | Q31: L-0000030 | R31: 131ak000001XjDvAAK | S31: FALSE | T31: FALSE | U31: L-0000030 | V31: 15:00:00.000Z | W31: No Show | X31: a07ak00001rZMpEAAW | Y31: Kennedy Sullivan | Z31: 2026-09-16T17:01:26.000Z | AA31: =ISNUMBER(SEARCH(";"&Lessons[[#This Row],[Instrument__c]]&";",";"&_xlfn.XLOOKUP(Lessons[[#This Row],[Instructor_External_Id__c]], Instructors[Id], Instructors[Instruments_Taught__c])&";")) -> TRUE | AB31: =IF(LEFT(Lessons[[#This Row],[Status__c]],9)="Cancelled","",Lessons[[#This Row],[Instructor_External_Id__c]]&"|"&TEXT(Lessons[[#This Row],[Lesson_Date__c]],"yyyy-mm-dd")&"|"&Lessons[[#This Row],[Start_Time__c]]) -> a06ak00000amzCJAAY|2026-05-15|15:00:00.000Z | AC31: =IF(Lessons[[#This Row],[Double Booked Key]]="","",COUNTIF(Lessons[Double Booked Key],Lessons[[#This Row],[Double Booked Key]])) -> 1 | AD31: =_xlfn.XLOOKUP(Lessons[[#This Row],[Location_External_Id__c]], Locations[Location Id], Locations[Location Name]) -> Toms River | AE31: =TEXT(Lessons[[#This Row],[Lesson_Date__c]], "yyyy-mm") -> 2026-05 | AF31: =IF(Lessons[[#This Row],[Lesson_Date__c]]<=Data_Audit!$F$1, "Yes", "No") -> Yes
A32: 005ak00000icyWTAAY | B32: 2026-09-14T21:01:58.000Z | C32: 30 | D32: a0Aak00000FtDm3EAF | E32: a06ak00000amzCJAAY | F32: Sofia Harris | G32: Reviewed last week&#39;s assignment. | H32: Violin | I32: FALSE | K32: 005ak00000icyWTAAY | L32: 2026-09-16T17:01:26.000Z | M32: 2026-09-15T17:27:06.000Z | N32: 2026-09-15T17:27:06.000Z | O32: 46057 | P32: LSN-00031 | Q32: L-0000031 | R32: 131ak000001XjDvAAK | S32: FALSE | T32: FALSE | U32: L-0000031 | V32: 17:00:00.000Z | W32: Completed | X32: a07ak00001rZMpEAAW | Y32: Kennedy Sullivan | Z32: 2026-09-16T17:01:26.000Z | AA32: =ISNUMBER(SEARCH(";"&Lessons[[#This Row],[Instrument__c]]&";",";"&_xlfn.XLOOKUP(Lessons[[#This Row],[Instructor_External_Id__c]], Instructors[Id], Instructors[Instruments_Taught__c])&";")) -> TRUE | AB32: =IF(LEFT(Lessons[[#This Row],[Status__c]],9)="Cancelled","",Lessons[[#This Row],[Instructor_External_Id__c]]&"|"&TEXT(Lessons[[#This Row],[Lesson_Date__c]],"yyyy-mm-dd")&"|"&Lessons[[#This Row],[Start_Time__c]]) -> a06ak00000amzCJAAY|2026-02-04|17:00:00.000Z | AC32: =IF(Lessons[[#This Row],[Double Booked Key]]="","",COUNTIF(Lessons[Double Booked Key],Lessons[[#This Row],[Double Booked Key]])) -> 1 | AD32: =_xlfn.XLOOKUP(Lessons[[#This Row],[Location_External_Id__c]], Locations[Location Id], Locations[Location Name]) -> Toms River | AE32: =TEXT(Lessons[[#This Row],[Lesson_Date__c]], "yyyy-mm") -> 2026-02 | AF32: =IF(Lessons[[#This Row],[Lesson_Date__c]]<=Data_Audit!$F$1, "Yes", "No") -> Yes
A33: 005ak00000icyWTAAY | B33: 2026-09-14T21:01:58.000Z | C33: 60 | D33: a0Aak00000FtDm4EAF | E33: a06ak00000amzCJAAY | F33: Sofia Harris | G33: Reviewed last week&#39;s assignment. | H33: Violin | I33: FALSE | K33: 005ak00000icyWTAAY | L33: 2026-09-16T17:01:26.000Z | M33: 2026-09-15T17:27:06.000Z | N33: 2026-09-15T17:27:06.000Z | O33: 46159 | P33: LSN-00032 | Q33: L-0000032 | R33: 131ak000001XjDvAAK | S33: FALSE | T33: FALSE | U33: L-0000032 | V33: 11:00:00.000Z | W33: Completed | X33: a07ak00001rZMpEAAW | Y33: Kennedy Sullivan | Z33: 2026-09-16T17:01:26.000Z | AA33: =ISNUMBER(SEARCH(";"&Lessons[[#This Row],[Instrument__c]]&";",";"&_xlfn.XLOOKUP(Lessons[[#This Row],[Instructor_External_Id__c]], Instructors[Id], Instructors[Instruments_Taught__c])&";")) -> TRUE | AB33: =IF(LEFT(Lessons[[#This Row],[Status__c]],9)="Cancelled","",Lessons[[#This Row],[Instructor_External_Id__c]]&"|"&TEXT(Lessons[[#This Row],[Lesson_Date__c]],"yyyy-mm-dd")&"|"&Lessons[[#This Row],[Start_Time__c]]) -> a06ak00000amzCJAAY|2026-05-17|11:00:00.000Z | AC33: =IF(Lessons[[#This Row],[Double Booked Key]]="","",COUNTIF(Lessons[Double Booked Key],Lessons[[#This Row],[Double Booked Key]])) -> 1 | AD33: =_xlfn.XLOOKUP(Lessons[[#This Row],[Location_External_Id__c]], Locations[Location Id], Locations[Location Name]) -> Toms River | AE33: =TEXT(Lessons[[#This Row],[Lesson_Date__c]], "yyyy-mm") -> 2026-05 | AF33: =IF(Lessons[[#This Row],[Lesson_Date__c]]<=Data_Audit!$F$1, "Yes", "No") -> Yes
A34: 005ak00000icyWTAAY | B34: 2026-09-14T21:01:58.000Z | C34: 30 | D34: a0Aak00000FtDm5EAF | E34: a06ak00000amzCJAAY | F34: Sofia Harris | H34: Violin | I34: FALSE | K34: 005ak00000icyWTAAY | L34: 2026-09-16T17:01:26.000Z | M34: 2026-09-15T17:27:06.000Z | N34: 2026-09-15T17:27:06.000Z | O34: 46195 | P34: LSN-00033 | Q34: L-0000033 | R34: 131ak000001XjDvAAK | S34: FALSE | T34: FALSE | U34: L-0000033 | V34: 10:00:00.000Z | W34: Completed | X34: a07ak00001rZMpEAAW | Y34: Kennedy Sullivan | Z34: 2026-09-16T17:01:26.000Z | AA34: =ISNUMBER(SEARCH(";"&Lessons[[#This Row],[Instrument__c]]&";",";"&_xlfn.XLOOKUP(Lessons[[#This Row],[Instructor_External_Id__c]], Instructors[Id], Instructors[Instruments_Taught__c])&";")) -> TRUE | AB34: =IF(LEFT(Lessons[[#This Row],[Status__c]],9)="Cancelled","",Lessons[[#This Row],[Instructor_External_Id__c]]&"|"&TEXT(Lessons[[#This Row],[Lesson_Date__c]],"yyyy-mm-dd")&"|"&Lessons[[#This Row],[Start_Time__c]]) -> a06ak00000amzCJAAY|2026-06-22|10:00:00.000Z | AC34: =IF(Lessons[[#This Row],[Double Booked Key]]="","",COUNTIF(Lessons[Double Booked Key],Lessons[[#This Row],[Double Booked Key]])) -> 1 | AD34: =_xlfn.XLOOKUP(Lessons[[#This Row],[Location_External_Id__c]], Locations[Location Id], Locations[Location Name]) -> Toms River | AE34: =TEXT(Lessons[[#This Row],[Lesson_Date__c]], "yyyy-mm") -> 2026-06 | AF34: =IF(Lessons[[#This Row],[Lesson_Date__c]]<=Data_Audit!$F$1, "Yes", "No") -> Yes
A35: 005ak00000icyWTAAY | B35: 2026-09-14T21:01:58.000Z | C35: 30 | D35: a0Aak00000FtDm6EAF | E35: a06ak00000amzBeAAI | F35: Zoey Rodriguez | G35: Focused on sight reading. | H35: Bass Guitar | I35: FALSE | K35: 005ak00000icyWTAAY | L35: 2026-09-16T17:01:26.000Z | M35: 2026-09-15T17:27:06.000Z | N35: 2026-09-15T17:27:06.000Z | O35: 46183 | P35: LSN-00034 | Q35: L-0000034 | R35: 131ak000001XjDuAAK | S35: FALSE | T35: FALSE | U35: L-0000034 | V35: 15:00:00.000Z | W35: Completed | X35: a07ak00001rZMpFAAW | Y35: Vincent Jones | Z35: 2026-09-16T17:01:26.000Z | AA35: =ISNUMBER(SEARCH(";"&Lessons[[#This Row],[Instrument__c]]&";",";"&_xlfn.XLOOKUP(Lessons[[#This Row],[Instructor_External_Id__c]], Instructors[Id], Instructors[Instruments_Taught__c])&";")) -> TRUE | AB35: =IF(LEFT(Lessons[[#This Row],[Status__c]],9)="Cancelled","",Lessons[[#This Row],[Instructor_External_Id__c]]&"|"&TEXT(Lessons[[#This Row],[Lesson_Date__c]],"yyyy-mm-dd")&"|"&Lessons[[#This Row],[Start_Time__c]]) -> a06ak00000amzBeAAI|2026-06-10|15:00:00.000Z | AC35: =IF(Lessons[[#This Row],[Double Booked Key]]="","",COUNTIF(Lessons[Double Booked Key],Lessons[[#This Row],[Double Booked Key]])) -> 1 | AD35: =_xlfn.XLOOKUP(Lessons[[#This Row],[Location_External_Id__c]], Locations[Location Id], Locations[Location Name]) -> Brick | AE35: =TEXT(Lessons[[#This Row],[Lesson_Date__c]], "yyyy-mm") -> 2026-06 | AF35: =IF(Lessons[[#This Row],[Lesson_Date__c]]<=Data_Audit!$F$1, "Yes", "No") -> Yes
A36: 005ak00000icyWTAAY | B36: 2026-09-14T21:01:58.000Z | C36: 30 | D36: a0Aak00000FtDm7EAF | E36: a06ak00000amzBeAAI | F36: Zoey Rodriguez | G36: Good progress on technique. | H36: Bass Guitar | I36: FALSE | K36: 005ak00000icyWTAAY | L36: 2026-09-16T17:01:26.000Z | M36: 2026-09-15T17:27:06.000Z | N36: 2026-09-15T17:27:06.000Z | O36: 46214 | P36: LSN-00035 | Q36: L-0000035 | R36: 131ak000001XjDuAAK | S36: FALSE | T36: FALSE | U36: L-0000035 | V36: 15:00:00.000Z | W36: Completed | X36: a07ak00001rZMpFAAW | Y36: Vincent Jones | Z36: 2026-09-16T17:01:26.000Z | AA36: =ISNUMBER(SEARCH(";"&Lessons[[#This Row],[Instrument__c]]&";",";"&_xlfn.XLOOKUP(Lessons[[#This Row],[Instructor_External_Id__c]], Instructors[Id], Instructors[Instruments_Taught__c])&";")) -> TRUE | AB36: =IF(LEFT(Lessons[[#This Row],[Status__c]],9)="Cancelled","",Lessons[[#This Row],[Instructor_External_Id__c]]&"|"&TEXT(Lessons[[#This Row],[Lesson_Date__c]],"yyyy-mm-dd")&"|"&Lessons[[#This Row],[Start_Time__c]]) -> a06ak00000amzBeAAI|2026-07-11|15:00:00.000Z | AC36: =IF(Lessons[[#This Row],[Double Booked Key]]="","",COUNTIF(Lessons[Double Booked Key],Lessons[[#This Row],[Double Booked Key]])) -> 1 | AD36: =_xlfn.XLOOKUP(Lessons[[#This Row],[Location_External_Id__c]], Locations[Location Id], Locations[Location Name]) -> Brick | AE36: =TEXT(Lessons[[#This Row],[Lesson_Date__c]], "yyyy-mm") -> 2026-07 | AF36: =IF(Lessons[[#This Row],[Lesson_Date__c]]<=Data_Audit!$F$1, "Yes", "No") -> Yes
A37: 005ak00000icyWTAAY | B37: 2026-09-14T21:01:58.000Z | C37: 30 | D37: a0Aak00000FtDm8EAF | E37: a06ak00000amzBeAAI | F37: Zoey Rodriguez | H37: Bass Guitar | I37: FALSE | K37: 005ak00000icyWTAAY | L37: 2026-09-16T17:01:26.000Z | M37: 2026-09-15T17:27:06.000Z | N37: 2026-09-15T17:27:06.000Z | O37: 46287 | P37: LSN-00036 | Q37: L-0000036 | R37: 131ak000001XjDuAAK | S37: TRUE | T37: TRUE | U37: L-0000036 | V37: 15:30:00.000Z | W37: Cancelled by Instructor | X37: a07ak00001rZMpFAAW | Y37: Vincent Jones | Z37: 2026-09-16T17:01:26.000Z | AA37: =ISNUMBER(SEARCH(";"&Lessons[[#This Row],[Instrument__c]]&";",";"&_xlfn.XLOOKUP(Lessons[[#This Row],[Instructor_External_Id__c]], Instructors[Id], Instructors[Instruments_Taught__c])&";")) -> TRUE | AB37: =IF(LEFT(Lessons[[#This Row],[Status__c]],9)="Cancelled","",Lessons[[#This Row],[Instructor_External_Id__c]]&"|"&TEXT(Lessons[[#This Row],[Lesson_Date__c]],"yyyy-mm-dd")&"|"&Lessons[[#This Row],[Start_Time__c]]) | AC37: =IF(Lessons[[#This Row],[Double Booked Key]]="","",COUNTIF(Lessons[Double Booked Key],Lessons[[#This Row],[Double Booked Key]])) | AD37: =_xlfn.XLOOKUP(Lessons[[#This Row],[Location_External_Id__c]], Locations[Location Id], Locations[Location Name]) -> Brick | AE37: =TEXT(Lessons[[#This Row],[Lesson_Date__c]], "yyyy-mm") -> 2026-09 | AF37: =IF(Lessons[[#This Row],[Lesson_Date__c]]<=Data_Audit!$F$1, "Yes", "No") -> Yes
A38: 005ak00000icyWTAAY | B38: 2026-09-14T21:01:58.000Z | C38: 30 | D38: a0Aak00000FtDm9EAF | E38: a06ak00000amzBeAAI | F38: Zoey Rodriguez | G38: Focused on sight reading. | H38: Bass Guitar | I38: FALSE | K38: 005ak00000icyWTAAY | L38: 2026-09-16T17:01:26.000Z | M38: 2026-09-15T17:27:06.000Z | N38: 2026-09-15T17:27:06.000Z | O38: 46237 | P38: LSN-00037 | Q38: L-0000037 | R38: 131ak000001XjDuAAK | S38: FALSE | T38: FALSE | U38: L-0000037 | V38: 11:00:00.000Z | W38: Completed | X38: a07ak00001rZMpFAAW | Y38: Vincent Jones | Z38: 2026-09-16T17:01:26.000Z | AA38: =ISNUMBER(SEARCH(";"&Lessons[[#This Row],[Instrument__c]]&";",";"&_xlfn.XLOOKUP(Lessons[[#This Row],[Instructor_External_Id__c]], Instructors[Id], Instructors[Instruments_Taught__c])&";")) -> TRUE | AB38: =IF(LEFT(Lessons[[#This Row],[Status__c]],9)="Cancelled","",Lessons[[#This Row],[Instructor_External_Id__c]]&"|"&TEXT(Lessons[[#This Row],[Lesson_Date__c]],"yyyy-mm-dd")&"|"&Lessons[[#This Row],[Start_Time__c]]) -> a06ak00000amzBeAAI|2026-08-03|11:00:00.000Z | AC38: =IF(Lessons[[#This Row],[Double Booked Key]]="","",COUNTIF(Lessons[Double Booked Key],Lessons[[#This Row],[Double Booked Key]])) -> 1 | AD38: =_xlfn.XLOOKUP(Lessons[[#This Row],[Location_External_Id__c]], Locations[Location Id], Locations[Location Name]) -> Brick | AE38: =TEXT(Lessons[[#This Row],[Lesson_Date__c]], "yyyy-mm") -> 2026-08 | AF38: =IF(Lessons[[#This Row],[Lesson_Date__c]]<=Data_Audit!$F$1, "Yes", "No") -> Yes
A39: 005ak00000icyWTAAY | B39: 2026-09-14T21:01:58.000Z | C39: 30 | D39: a0Aak00000FtDmAEAV | E39: a06ak00000amzBeAAI | F39: Zoey Rodriguez | G39: Started new piece. | H39: Bass Guitar | I39: FALSE | K39: 005ak00000icyWTAAY | L39: 2026-09-16T17:01:26.000Z | M39: 2026-09-15T17:27:06.000Z | N39: 2026-09-15T17:27:06.000Z | O39: 46170 | P39: LSN-00038 | Q39: L-0000038 | R39: 131ak000001XjDuAAK | S39: FALSE | T39: FALSE | U39: L-0000038 | V39: 19:00:00.000Z | W39: Completed | X39: a07ak00001rZMpFAAW | Y39: Vincent Jones | Z39: 2026-09-16T17:01:26.000Z | AA39: =ISNUMBER(SEARCH(";"&Lessons[[#This Row],[Instrument__c]]&";",";"&_xlfn.XLOOKUP(Lessons[[#This Row],[Instructor_External_Id__c]], Instructors[Id], Instructors[Instruments_Taught__c])&";")) -> TRUE | AB39: =IF(LEFT(Lessons[[#This Row],[Status__c]],9)="Cancelled","",Lessons[[#This Row],[Instructor_External_Id__c]]&"|"&TEXT(Lessons[[#This Row],[Lesson_Date__c]],"yyyy-mm-dd")&"|"&Lessons[[#This Row],[Start_Time__c]]) -> a06ak00000amzBeAAI|2026-05-28|19:00:00.000Z | AC39: =IF(Lessons[[#This Row],[Double Booked Key]]="","",COUNTIF(Lessons[Double Booked Key],Lessons[[#This Row],[Double Booked Key]])) -> 1 | AD39: =_xlfn.XLOOKUP(Lessons[[#This Row],[Location_External_Id__c]], Locations[Location Id], Locations[Location Name]) -> Brick | AE39: =TEXT(Lessons[[#This Row],[Lesson_Date__c]], "yyyy-mm") -> 2026-05 | AF39: =IF(Lessons[[#This Row],[Lesson_Date__c]]<=Data_Audit!$F$1, "Yes", "No") -> Yes
A40: 005ak00000icyWTAAY | B40: 2026-09-14T21:01:58.000Z | C40: 30 | D40: a0Aak00000FtDmBEAV | E40: a06ak00000amzC5AAI | F40: Penelope Wilson | H40: Drums | I40: FALSE | K40: 005ak00000icyWTAAY | L40: 2026-09-16T17:01:26.000Z | M40: 2026-09-15T17:27:06.000Z | N40: 2026-09-15T17:27:06.000Z | O40: 46087 | P40: LSN-00039 | Q40: L-0000039 | R40: 131ak000001XjDuAAK | S40: FALSE | T40: FALSE | U40: L-0000039 | V40: 18:00:00.000Z | W40: Cancelled by Student | X40: a07ak00001rZMpGAAW | Y40: Noah Wright | Z40: 2026-09-16T17:01:26.000Z | AA40: =ISNUMBER(SEARCH(";"&Lessons[[#This Row],[Instrument__c]]&";",";"&_xlfn.XLOOKUP(Lessons[[#This Row],[Instructor_External_Id__c]], Instructors[Id], Instructors[Instruments_Taught__c])&";")) -> TRUE | AB40: =IF(LEFT(Lessons[[#This Row],[Status__c]],9)="Cancelled","",Lessons[[#This Row],[Instructor_External_Id__c]]&"|"&TEXT(Lessons[[#This Row],[Lesson_Date__c]],"yyyy-mm-dd")&"|"&Lessons[[#This Row],[Start_Time__c]]) | AC40: =IF(Lessons[[#This Row],[Double Booked Key]]="","",COUNTIF(Lessons[Double Booked Key],Lessons[[#This Row],[Double Booked Key]])) | AD40: =_xlfn.XLOOKUP(Lessons[[#This Row],[Location_External_Id__c]], Locations[Location Id], Locations[Location Name]) -> Brick | AE40: =TEXT(Lessons[[#This Row],[Lesson_Date__c]], "yyyy-mm") -> 2026-03 | AF40: =IF(Lessons[[#This Row],[Lesson_Date__c]]<=Data_Audit!$F$1, "Yes", "No") -> Yes
...

Sheet Lesson Health
D1: Is Past | E1: Yes | M1: Is Past | N1: Yes
M2: Status__c | N2: Completed
D3: Count of Id | E3: Status__c
A4: Location | B4: Cancellation Rate(By Location) | C4: No-Show Rate(By Location) | D4: Instrument__c | E4: Scheduled | F4: No Show | G4: Completed | H4: Cancelled by Student | I4: Cancelled by Instructor | J4: Grand Total | K4: Cancellation Rate(By Instrument) | L4: No-Show Rate(By Instrument) | M4: Lesson Month | N4: Count of Id
